Workbook

Sheet songs
A1: artist_id | B1: artist_name | C1: song | D1: duration_ms | E1: duration_seconds | F1: explicit | G1: year_id | H1: year | I1: popularity | J1: danceability | K1: energy | L1: energy_category | M1: loudness | N1: speechiness | O1: acousticness | P1: instrumentalness | Q1: liveness | R1: valence | S1: song_mood | T1: tempo | U1: genre
A2: 619 | B2: =_xlfn.xlookup(A2, artists!A$2:A$836, artists!B$2:B$836) -> The Chainsmokers | C2: #SELFIE - Original Mix | D2: 183750 | E2: =D2/1000 -> 183.75 | F2: =FALSE() -> FALSE | G2: 17 | H2: =_xlfn.xlookup(G2, years!A$2:A$836, years!B$2:B$836) -> 2014 | I2: 0 | J2: 0.789 | K2: 0.915 | L2: =IF(K2>0.66,"High",IF(K2>0.33&K2<=0.66,"Medium","Low")) -> High | M2: -3.263 | N2: 0.248 | O2: 0.0135 | P2: 8.77e-06 | Q2: 0.0818 | R2: 0.66 | S2: =IF(R2 >= 0.5, "Positive", "Negative") -> Positive | T2: 127.955 | U2: pop, Dance/Electronic
A3: 404 | B3: =_xlfn.xlookup(A3, artists!A$2:A$836, artists!B$2:B$836) -> will.i.am | C3: #thatPOWER | D3: 279506 | E3: =D3/1000 -> 279.506 | F3: =FALSE() -> FALSE | G3: 16 | H3: =_xlfn.xlookup(G3, years!A$2:A$836, years!B$2:B$836) -> 2013 | I3: 68 | J3: 0.797 | K3: 0.608 | L3: =IF(K3>0.66,"High",IF(K3>0.33&K3<=0.66,"Medium","Low")) -> Low | M3: -6.096 | N3: 0.0584 | O3: 0.00112 | P3: 7.66e-05 | Q3: 0.0748 | R3: 0.402 | S3: =IF(R3 >= 0.5, "Positive", "Negative") -> Negative | T3: 127.999 | U3: hip hop, pop
A4: 169 | B4: =_xlfn.xlookup(A4, artists!A$2:A$836, artists!B$2:B$836) -> Sean Paul | C4: (When You Gonna) Give It Up to Me (feat. Keyshia Cole) - Radio Version | D4: 243880 | E4: =D4/1000 -> 243.88 | F4: =FALSE() -> FALSE | G4: 9 | H4: =_xlfn.xlookup(G4, years!A$2:A$836, years!B$2:B$836) -> 2006 | I4: 58 | J4: 0.711 | K4: 0.761 | L4: =IF(K4>0.66,"High",IF(K4>0.33&K4<=0.66,"Medium","Low")) -> High | M4: -3.04 | N4: 0.225 | O4: 0.067 | P4: 0 | Q4: 0.041 | R4: 0.718 | S4: =IF(R4 >= 0.5, "Positive", "Negative") -> Positive | T4: 95.824 | U4: hip hop, pop
A5: 669 | B5: =_xlfn.xlookup(A5, artists!A$2:A$836, artists!B$2:B$836) -> Tame Impala | C5: The Less I Know The Better | D5: 216320 | E5: =D5/1000 -> 216.32 | F5: =TRUE() -> TRUE | G5: 18 | H5: =_xlfn.xlookup(G5, years!A$2:A$836, years!B$2:B$836) -> 2015 | I5: 83 | J5: 0.64 | K5: 0.74 | L5: =IF(K5>0.66,"High",IF(K5>0.33&K5<=0.66,"Medium","Low")) -> High | M5: -4.083 | N5: 0.0284 | O5: 0.0115 | P5: 0.00678 | Q5: 0.167 | R5: 0.785 | S5: =IF(R5 >= 0.5, "Positive", "Negative") -> Positive | T5: 116.879 | U5: metal
A6: 35 | B6: =_xlfn.xlookup(A6, artists!A$2:A$836, artists!B$2:B$836) -> JAY-Z | C6: 03' Bonnie & Clyde | D6: 205560 | E6: =D6/1000 -> 205.56 | F6: =TRUE() -> TRUE | G6: 5 | H6: =_xlfn.xlookup(G6, years!A$2:A$836, years!B$2:B$836) -> 2002 | I6: 71 | J6: 0.759 | K6: 0.678 | L6: =IF(K6>0.66,"High",IF(K6>0.33&K6<=0.66,"Medium","Low")) -> High | M6: -5.148 | N6: 0.314 | O6: 0.23 | P6: 0 | Q6: 0.15 | R6: 0.327 | S6: =IF(R6 >= 0.5, "Positive", "Negative") -> Negative | T6: 89.64 | U6: hip hop
A7: 301 | B7: =_xlfn.xlookup(A7, artists!A$2:A$836, artists!B$2:B$836) -> Amerie | C7: 1 Thing | D7: 238746 | E7: =D7/1000 -> 238.746 | F7: =FALSE() -> FALSE | G7: 11 | H7: =_xlfn.xlookup(G7, years!A$2:A$836, years!B$2:B$836) -> 2008 | I7: 52 | J7: 0.636 | K7: 0.946 | L7: =IF(K7>0.66,"High",IF(K7>0.33&K7<=0.66,"Medium","Low")) -> High | M7: -4.683 | N7: 0.332 | O7: 0.115 | P7: 3.75e-05 | Q7: 0.0416 | R7: 0.891 | S7: =IF(R7 >= 0.5, "Positive", "Negative") -> Positive | T7: 125.085 | U7: hip hop, pop, R&B
A8: 249 | B8: =_xlfn.xlookup(A8, artists!A$2:A$836, artists!B$2:B$836) -> Ciara | C8: 1, 2 Step (feat. Missy Elliott) - Main | D8: 202213 | E8: =D8/1000 -> 202.213 | F8: =FALSE() -> FALSE | G8: 8 | H8: =_xlfn.xlookup(G8, years!A$2:A$836, years!B$2:B$836) -> 2005 | I8: 52 | J8: 0.939 | K8: 0.498 | L8: =IF(K8>0.66,"High",IF(K8>0.33&K8<=0.66,"Medium","Low")) -> Low | M8: -10.94 | N8: 0.161 | O8: 0.0444 | P8: 0.00128 | Q8: 0.0475 | R8: 0.801 | S8: =IF(R8 >= 0.5, "Positive", "Negative") -> Positive | T8: 113.053 | U8: pop, R&B
A9: 180 | B9: =_xlfn.xlookup(A9, artists!A$2:A$836, artists!B$2:B$836) -> Coldplay | C9: Hymn for the Weekend | D9: 258266 | E9: =D9/1000 -> 258.266 | F9: =FALSE() -> FALSE | G9: 18 | H9: =_xlfn.xlookup(G9, years!A$2:A$836, years!B$2:B$836) -> 2015 | I9: 82 | J9: 0.491 | K9: 0.693 | L9: =IF(K9>0.66,"High",IF(K9>0.33&K9<=0.66,"Medium","Low")) -> High | M9: -6.487 | N9: 0.0377 | O9: 0.211 | P9: 6.92e-06 | Q9: 0.325 | R9: 0.412 | S9: =IF(R9 >= 0.5, "Positive", "Negative") -> Negative | T9: 90.027 | U9: rock, pop
A10: 781 | B10: =_xlfn.xlookup(A10, artists!A$2:A$836, artists!B$2:B$836) -> MK | C10: 17 | D10: 196489 | E10: =D10/1000 -> 196.489 | F10: =FALSE() -> FALSE | G10: 20 | H10: =_xlfn.xlookup(G10, years!A$2:A$836, years!B$2:B$836) -> 2017 | I10: 65 | J10: 0.703 | K10: 0.832 | L10: =IF(K10>0.66,"High",IF(K10>0.33&K10<=0.66,"Medium","Low")) -> High | M10: -7.202 | N10: 0.0689 | O10: 0.00149 | P10: 0.127 | Q10: 0.0696 | R10: 0.667 | S10: =IF(R10 >= 0.5, "Positive", "Negative") -> Positive | T10: 122.029 | U10: pop, Dance/Electronic
A11: 714 | B11: =_xlfn.xlookup(A11, artists!A$2:A$836, artists!B$2:B$836) -> Hilltop Hoods | C11: 1955 | D11: 239280 | E11: =D11/1000 -> 239.28 | F11: =FALSE() -> FALSE | G11: 19 | H11: =_xlfn.xlookup(G11, years!A$2:A$836, years!B$2:B$836) -> 2016 | I11: 63 | J11: 0.766 | K11: 0.5 | L11: =IF(K11>0.66,"High",IF(K11>0.33&K11<=0.66,"Medium","Low")) -> Low | M11: -7.558 | N11: 0.0695 | O11: 0.719 | P11: 5.91e-06 | Q11: 0.304 | R11: 0.71 | S11: =IF(R11 >= 0.5, "Positive", "Negative") -> Positive | T11: 84.044 | U11: hip hop, pop
A12: 284 | B12: =_xlfn.xlookup(A12, artists!A$2:A$836, artists!B$2:B$836) -> James Blunt | C12: 1973 | D12: 280026 | E12: =D12/1000 -> 280.026 | F12: =FALSE() -> FALSE | G12: 10 | H12: =_xlfn.xlookup(G12, years!A$2:A$836, years!B$2:B$836) -> 2007 | I12: 68 | J12: 0.72 | K12: 0.668 | L12: =IF(K12>0.66,"High",IF(K12>0.33&K12<=0.66,"Medium","Low")) -> High | M12: -7.928 | N12: 0.0269 | O12: 0.0652 | P12: 0.00664 | Q12: 0.0789 | R12: 0.768 | S12: =IF(R12 >= 0.5, "Positive", "Negative") -> Positive | T12: 123.007 | U12: pop
A13: 611 | B13: =_xlfn.xlookup(A13, artists!A$2:A$836, artists!B$2:B$836) -> Tinashe | C13: 2 On (feat. ScHoolboy Q) | D13: 227000 | E13: =D13/1000 -> 227 | F13: =TRUE() -> TRUE | G13: 17 | H13: =_xlfn.xlookup(G13, years!A$2:A$836, years!B$2:B$836) -> 2014 | I13: 71 | J13: 0.742 | K13: 0.595 | L13: =IF(K13>0.66,"High",IF(K13>0.33&K13<=0.66,"Medium","Low")) -> Low | M13: -7.51 | N13: 0.107 | O13: 0.15 | P13: 0 | Q13: 0.111 | R13: 0.431 | S13: =IF(R13 >= 0.5, "Positive", "Negative") -> Negative | T13: 101.013 | U13: hip hop, pop, R&B, Dance/Electronic
A14: 336 | B14: =_xlfn.xlookup(A14, artists!A$2:A$836, artists!B$2:B$836) -> Fall Out Boy | C14: Centuries | D14: 228360 | E14: =D14/1000 -> 228.36 | F14: =FALSE() -> FALSE | G14: 18 | H14: =_xlfn.xlookup(G14, years!A$2:A$836, years!B$2:B$836) -> 2015 | I14: 80 | J14: 0.393 | K14: 0.858 | L14: =IF(K14>0.66,"High",IF(K14>0.33&K14<=0.66,"Medium","Low")) -> High | M14: -2.868 | N14: 0.0729 | O14: 0.00359 | P14: 0 | Q14: 0.102 | R14: 0.56 | S14: =IF(R14 >= 0.5, "Positive", "Negative") -> Positive | T14: 176.042 | U14: rock
A15: 698 | B15: =_xlfn.xlookup(A15, artists!A$2:A$836, artists!B$2:B$836) -> Anne-Marie | C15: 2002 | D15: 186986 | E15: =D15/1000 -> 186.986 | F15: =FALSE() -> FALSE | G15: 21 | H15: =_xlfn.xlookup(G15, years!A$2:A$836, years!B$2:B$836) -> 2018 | I15: 80 | J15: 0.697 | K15: 0.683 | L15: =IF(K15>0.66,"High",IF(K15>0.33&K15<=0.66,"Medium","Low")) -> High | M15: -2.881 | N15: 0.117 | O15: 0.0372 | P15: 0 | Q15: 0.137 | R15: 0.603 | S15: =IF(R15 >= 0.5, "Positive", "Negative") -> Positive | T15: 96.133 | U15: pop, Dance/Electronic
A16: 271 | B16: =_xlfn.xlookup(A16, artists!A$2:A$836, artists!B$2:B$836) -> Green Day | C16: 21 Guns | D16: 321093 | E16: =D16/1000 -> 321.093 | F16: =FALSE() -> FALSE | G16: 12 | H16: =_xlfn.xlookup(G16, years!A$2:A$836, years!B$2:B$836) -> 2009 | I16: 73 | J16: 0.268 | K16: 0.742 | L16: =IF(K16>0.66,"High",IF(K16>0.33&K16<=0.66,"Medium","Low")) -> High | M16: -4.939 | N16: 0.0355 | O16: 0.0518 | P16: 0 | Q16: 0.626 | R16: 0.416 | S16: =IF(R16 >= 0.5, "Positive", "Negative") -> Negative | T16: 159.779 | U16: rock
A17: 191 | B17: =_xlfn.xlookup(A17, artists!A$2:A$836, artists!B$2:B$836) -> 50 Cent | C17: 21 Questions | D17: 224440 | E17: =D17/1000 -> 224.44 | F17: =TRUE() -> TRUE | G17: 6 | H17: =_xlfn.xlookup(G17, years!A$2:A$836, years!B$2:B$836) -> 2003 | I17: 72 | J17: 0.646 | K17: 0.813 | L17: =IF(K17>0.66,"High",IF(K17>0.33&K17<=0.66,"Medium","Low")) -> High | M17: -3.846 | N17: 0.299 | O17: 0.349 | P17: 9.37e-05 | Q17: 0.0427 | R17: 0.895 | S17: =IF(R17 >= 0.5, "Positive", "Negative") -> Positive | T17: 92.729 | U17: hip hop, pop
A18: 135 | B18: =_xlfn.xlookup(A18, artists!A$2:A$836, artists!B$2:B$836) -> So Solid Crew | C18: 21 Seconds | D18: 302826 | E18: =D18/1000 -> 302.826 | F18: =TRUE() -> TRUE | G18: 4 | H18: =_xlfn.xlookup(G18, years!A$2:A$836, years!B$2:B$836) -> 2001 | I18: 51 | J18: 0.607 | K18: 0.637 | L18: =IF(K18>0.66,"High",IF(K18>0.33&K18<=0.66,"Medium","Low")) -> Low | M18: -11.072 | N18: 0.241 | O18: 0.0191 | P18: 0 | Q18: 0.124 | R18: 0.818 | S18: =IF(R18 >= 0.5, "Positive", "Negative") -> Positive | T18: 137.03 | U18: Dance/Electronic
A19: 545 | B19: =_xlfn.xlookup(A19, artists!A$2:A$836, artists!B$2:B$836) -> Azealia Banks | C19: 212 | D19: 204956 | E19: =D19/1000 -> 204.956 | F19: =TRUE() -> TRUE | G19: 17 | H19: =_xlfn.xlookup(G19, years!A$2:A$836, years!B$2:B$836) -> 2014 | I19: 0 | J19: 0.847 | K19: 0.769 | L19: =IF(K19>0.66,"High",IF(K19>0.33&K19<=0.66,"Medium","Low")) -> High | M19: -5.761 | N19: 0.258 | O19: 0.0145 | P19: 0.00012 | Q19: 0.0767 | R19: 0.626 | S19: =IF(R19 >= 0.5, "Positive", "Negative") -> Positive | T19: 126.017 | U19: hip hop, pop, R&B
A20: 439 | B20: =_xlfn.xlookup(A20, artists!A$2:A$836, artists!B$2:B$836) -> Taylor Swift | C20: 22 | D20: 232120 | E20: =D20/1000 -> 232.12 | F20: =FALSE() -> FALSE | G20: 15 | H20: =_xlfn.xlookup(G20, years!A$2:A$836, years!B$2:B$836) -> 2012 | I20: 68 | J20: 0.661 | K20: 0.729 | L20: =IF(K20>0.66,"High",IF(K20>0.33&K20<=0.66,"Medium","Low")) -> High | M20: -6.561 | N20: 0.0376 | O20: 0.00215 | P20: 0.0013 | Q20: 0.0477 | R20: 0.668 | S20: =IF(R20 >= 0.5, "Positive", "Negative") -> Positive | T20: 103.987 | U20: pop
A21: 651 | B21: =_xlfn.xlookup(A21, artists!A$2:A$836, artists!B$2:B$836) -> Twenty One Pilots | C21: Ride | D21: 214506 | E21: =D21/1000 -> 214.506 | F21: =FALSE() -> FALSE | G21: 18 | H21: =_xlfn.xlookup(G21, years!A$2:A$836, years!B$2:B$836) -> 2015 | I21: 80 | J21: 0.645 | K21: 0.713 | L21: =IF(K21>0.66,"High",IF(K21>0.33&K21<=0.66,"Medium","Low")) -> High | M21: -5.355 | N21: 0.0393 | O21: 0.00835 | P21: 0 | Q21: 0.113 | R21: 0.566 | S21: =IF(R21 >= 0.5, "Positive", "Negative") -> Positive | T21: 74.989 | U21: rock
A22: 438 | B22: =_xlfn.xlookup(A22, artists!A$2:A$836, artists!B$2:B$836) -> David Guetta | C22: 2U (feat. Justin Bieber) | D22: 194896 | E22: =D22/1000 -> 194.896 | F22: =FALSE() -> FALSE | G22: 20 | H22: =_xlfn.xlookup(G22, years!A$2:A$836, years!B$2:B$836) -> 2017 | I22: 67 | J22: 0.548 | K22: 0.65 | L22: =IF(K22>0.66,"High",IF(K22>0.33&K22<=0.66,"Medium","Low")) -> Low | M22: -5.827 | N22: 0.0591 | O22: 0.219 | P22: 0 | Q22: 0.225 | R22: 0.557 | S22: =IF(R22 >= 0.5, "Positive", "Negative") -> Positive | T22: 144.937 | U22: hip hop, pop, Dance/Electronic
A23: 827 | B23: =_xlfn.xlookup(A23, artists!A$2:A$836, artists!B$2:B$836) -> Dominic Fike | C23: 3 Nights | D23: 177666 | E23: =D23/1000 -> 177.666 | F23: =FALSE() -> FALSE | G23: 21 | H23: =_xlfn.xlookup(G23, years!A$2:A$836, years!B$2:B$836) -> 2018 | I23: 78 | J23: 0.815 | K23: 0.518 | L23: =IF(K23>0.66,"High",IF(K23>0.33&K23<=0.66,"Medium","Low")) -> Low | M23: -6.594 | N23: 0.0897 | O23: 0.223 | P23: 0 | Q23: 0.104 | R23: 0.877 | S23: =IF(R23 >= 0.5, "Positive", "Negative") -> Positive | T23: 151.891 | U23: rock, pop
A24: 598 | B24: =_xlfn.xlookup(A24, artists!A$2:A$836, artists!B$2:B$836) -> Childish Gambino | C24: 3005 | D24: 235662 | E24: =D24/1000 -> 235.662 | F24: =TRUE() -> TRUE | G24: 16 | H24: =_xlfn.xlookup(G24, years!A$2:A$836, years!B$2:B$836) -> 2013 | I24: 0 | J24: 0.681 | K24: 0.463 | L24: =IF(K24>0.66,"High",IF(K24>0.33&K24<=0.66,"Medium","Low")) -> Low | M24: -6.542 | N24: 0.289 | O24: 0.128 | P24: 0 | Q24: 0.0769 | R24: 0.661 | S24: =IF(R24 >= 0.5, "Positive", "Negative") -> Positive | T24: 82.92 | U24: hip hop
A25: 31 | B25: =_xlfn.xlookup(A25, artists!A$2:A$836, artists!B$2:B$836) -> Madonna | C25: 4 Minutes (feat. Justin Timberlake & Timbaland) | D25: 189693 | E25: =D25/1000 -> 189.693 | F25: =FALSE() -> FALSE | G25: 12 | H25: =_xlfn.xlookup(G25, years!A$2:A$836, years!B$2:B$836) -> 2009 | I25: 71 | J25: 0.753 | K25: 0.931 | L25: =IF(K25>0.66,"High",IF(K25>0.33&K25<=0.66,"Medium","Low")) -> High | M25: -4.922 | N25: 0.0652 | O25: 0.00994 | P25: 0.00696 | Q25: 0.234 | R25: 0.767 | S25: =IF(R25 >= 0.5, "Positive", "Negative") -> Positive | T25: 113.029 | U25: pop
A26: 41 | B26: =_xlfn.xlookup(A26, artists!A$2:A$836, artists!B$2:B$836) -> Missy Elliott | C26: 4 My People (feat. Eve) | D26: 289373 | E26: =D26/1000 -> 289.373 | F26: =TRUE() -> TRUE | G26: 4 | H26: =_xlfn.xlookup(G26, years!A$2:A$836, years!B$2:B$836) -> 2001 | I26: 49 | J26: 0.969 | K26: 0.701 | L26: =IF(K26>0.66,"High",IF(K26>0.33&K26<=0.66,"Medium","Low")) -> High | M26: -7.503 | N26: 0.156 | O26: 0.14 | P26: 0.00161 | Q26: 0.201 | R26: 0.905 | S26: =IF(R26 >= 0.5, "Positive", "Negative") -> Positive | T26: 121.392 | U26: hip hop, pop, R&B
A27: 402 | B27: =_xlfn.xlookup(A27, artists!A$2:A$836, artists!B$2:B$836) -> Lil Wayne | C27: 6 Foot 7 Foot | D27: 248586 | E27: =D27/1000 -> 248.586 | F27: =TRUE() -> TRUE | G27: 14 | H27: =_xlfn.xlookup(G27, years!A$2:A$836, years!B$2:B$836) -> 2011 | I27: 1 | J27: 0.364 | K27: 0.752 | L27: =IF(K27>0.66,"High",IF(K27>0.33&K27<=0.66,"Medium","Low")) -> High | M27: -5.429 | N27: 0.304 | O27: 0.0007 | P27: 0 | Q27: 0.318 | R27: 0.606 | S27: =IF(R27 >= 0.5, "Positive", "Negative") -> Positive | T27: 79.119 | U27: hip hop, pop
A28: 664 | B28: =_xlfn.xlookup(A28, artists!A$2:A$836, artists!B$2:B$836) -> Fetty Wap | C28: 679 (feat. Remy Boyz) | D28: 196693 | E28: =D28/1000 -> 196.693 | F28: =TRUE() -> TRUE | G28: 18 | H28: =_xlfn.xlookup(G28, years!A$2:A$836, years!B$2:B$836) -> 2015 | I28: 74 | J28: 0.618 | K28: 0.717 | L28: =IF(K28>0.66,"High",IF(K28>0.33&K28<=0.66,"Medium","Low")) -> High | M28: -5.738 | N28: 0.318 | O28: 0.00256 | P28: 0 | Q28: 0.625 | R28: 0.603 | S28: =IF(R28 >= 0.5, "Positive", "Negative") -> Positive | T28: 190.05 | U28: hip hop, pop
A29: 56 | B29: =_xlfn.xlookup(A29, artists!A$2:A$836, artists!B$2:B$836) -> Craig David | C29: 7 Days | D29: 235133 | E29: =D29/1000 -> 235.133 | F29: =FALSE() -> FALSE | G29: 3 | H29: =_xlfn.xlookup(G29, years!A$2:A$836, years!B$2:B$836) -> 2000 | I29: 70 | J29: 0.659 | K29: 0.812 | L29: =IF(K29>0.66,"High",IF(K29>0.33&K29<=0.66,"Medium","Low")) -> High | M29: -7.499 | N29: 0.0487 | O29: 0.23 | P29: 0 | Q29: 0.0951 | R29: 0.888 | S29: =IF(R29 >= 0.5, "Positive", "Negative") -> Positive | T29: 83.014 | U29: hip hop, pop, R&B
A30: 600 | B30: =_xlfn.xlookup(A30, artists!A$2:A$836, artists!B$2:B$836) -> Ariana Grande | C30: 7 rings | D30: 178626 | E30: =D30/1000 -> 178.626 | F30: =TRUE() -> TRUE | G30: 22 | H30: =_xlfn.xlookup(G30, years!A$2:A$836, years!B$2:B$836) -> 2019 | I30: 83 | J30: 0.778 | K30: 0.317 | L30: =IF(K30>0.66,"High",IF(K30>0.33&K30<=0.66,"Medium","Low")) -> Low | M30: -10.732 | N30: 0.334 | O30: 0.592 | P30: 0 | Q30: 0.0881 | R30: 0.327 | S30: =IF(R30 >= 0.5, "Positive", "Negative") -> Negative | T30: 140.048 | U30: pop
A31: 721 | B31: =_xlfn.xlookup(A31, artists!A$2:A$836, artists!B$2:B$836) -> Billie Eilish | C31: bad guy | D31: 194087 | E31: =D31/1000 -> 194.087 | F31: =FALSE() -> FALSE | G31: 22 | H31: =_xlfn.xlookup(G31, years!A$2:A$836, years!B$2:B$836) -> 2019 | I31: 83 | J31: 0.701 | K31: 0.425 | L31: =IF(K31>0.66,"High",IF(K31>0.33&K31<=0.66,"Medium","Low")) -> Low | M31: -10.965 | N31: 0.375 | O31: 0.328 | P31: 0.13 | Q31: 0.1 | R31: 0.562 | S31: =IF(R31 >= 0.5, "Positive", "Negative") -> Positive | T31: 135.128 | U31: pop, Dance/Electronic
A32: 184 | B32: =_xlfn.xlookup(A32, artists!A$2:A$836, artists!B$2:B$836) -> Elvis Presley | C32: A Little Less Conversation - JXL Radio Edit Remix | D32: 211506 | E32: =D32/1000 -> 211.506 | F32: =FALSE() -> FALSE | G32: 5 | H32: =_xlfn.xlookup(G32, years!A$2:A$836, years!B$2:B$836) -> 2002 | I32: 60 | J32: 0.597 | K32: 0.97 | L32: =IF(K32>0.66,"High",IF(K32>0.33&K32<=0.66,"Medium","Low")) -> High | M32: -5.972 | N32: 0.0502 | O32: 0.000385 | P32: 0.205 | Q32: 0.133 | R32: 0.717 | S32: =IF(R32 >= 0.5, "Positive", "Negative") -> Positive | T32: 114.999 | U32: rock, easy listening
A33: 725 | B33: =_xlfn.xlookup(A33, artists!A$2:A$836, artists!B$2:B$836) -> 21 Savage | C33: a lot | D33: 288624 | E33: =D33/1000 -> 288.624 | F33: =TRUE() -> TRUE | G33: 21 | H33: =_xlfn.xlookup(G33, years!A$2:A$836, years!B$2:B$836) -> 2018 | I33: 78 | J33: 0.837 | K33: 0.636 | L33: =IF(K33>0.66,"High",IF(K33>0.33&K33<=0.66,"Medium","Low")) -> Low | M33: -7.643 | N33: 0.086 | O33: 0.0395 | P33: 0.00125 | Q33: 0.342 | R33: 0.274 | S33: =IF(R33 >= 0.5, "Positive", "Negative") -> Negative | T33: 145.972 | U33: hip hop
A34: 402 | B34: =_xlfn.xlookup(A34, artists!A$2:A$836, artists!B$2:B$836) -> Lil Wayne | C34: A Milli | D34: 221840 | E34: =D34/1000 -> 221.84 | F34: =TRUE() -> TRUE | G34: 11 | H34: =_xlfn.xlookup(G34, years!A$2:A$836, years!B$2:B$836) -> 2008 | I34: 69 | J34: 0.674 | K34: 0.695 | L34: =IF(K34>0.66,"High",IF(K34>0.33&K34<=0.66,"Medium","Low")) -> High | M34: -8.636 | N34: 0.278 | O34: 0.0387 | P34: 0.00202 | Q34: 0.194 | R34: 0.773 | S34: =IF(R34 >= 0.5, "Positive", "Negative") -> Positive | T34: 151.486 | U34: hip hop, pop
A35: 337 | B35: =_xlfn.xlookup(A35, artists!A$2:A$836, artists!B$2:B$836) -> Leona Lewis | C35: A Moment Like This | D35: 257293 | E35: =D35/1000 -> 257.293 | F35: =FALSE() -> FALSE | G35: 10 | H35: =_xlfn.xlookup(G35, years!A$2:A$836, years!B$2:B$836) -> 2007 | I35: 57 | J35: 0.261 | K35: 0.562 | L35: =IF(K35>0.66,"High",IF(K35>0.33&K35<=0.66,"Medium","Low")) -> Low | M35: -3.667 | N35: 0.0301 | O35: 0.423 | P35: 7.54e-06 | Q35: 0.131 | R35: 0.167 | S35: =IF(R35 >= 0.5, "Positive", "Negative") -> Negative | T35: 70.543 | U35: pop, R&B
A36: 65 | B36: =_xlfn.xlookup(A36, artists!A$2:A$836, artists!B$2:B$836) -> Céline Dion | C36: A New Day Has Come - Radio Remix | D36: 259773 | E36: =D36/1000 -> 259.773 | F36: =FALSE() -> FALSE | G36: 4 | H36: =_xlfn.xlookup(G36, years!A$2:A$836, years!B$2:B$836) -> 2001 | I36: 59 | J36: 0.574 | K36: 0.691 | L36: =IF(K36>0.66,"High",IF(K36>0.33&K36<=0.66,"Medium","Low")) -> High | M36: -5.103 | N36: 0.035 | O36: 0.0826 | P36: 1.65e-05 | Q36: 0.149 | R36: 0.195 | S36: =IF(R36 >= 0.5, "Positive", "Negative") -> Negative | T36: 91.969 | U36: pop
A37: 180 | B37: =_xlfn.xlookup(A37, artists!A$2:A$836, artists!B$2:B$836) -> Coldplay | C37: A Sky Full of Stars | D37: 267866 | E37: =D37/1000 -> 267.866 | F37: =FALSE() -> FALSE | G37: 17 | H37: =_xlfn.xlookup(G37, years!A$2:A$836, years!B$2:B$836) -> 2014 | I37: 80 | J37: 0.545 | K37: 0.675 | L37: =IF(K37>0.66,"High",IF(K37>0.33&K37<=0.66,"Medium","Low")) -> High | M37: -6.474 | N37: 0.0279 | O37: 0.00617 | P37: 0.00197 | Q37: 0.209 | R37: 0.162 | S37: =IF(R37 >= 0.5, "Positive", "Negative") -> Negative | T37: 124.97 | U37: rock, pop
A38: 147 | B38: =_xlfn.xlookup(A38, artists!A$2:A$836, artists!B$2:B$836) -> Vanessa Carlton | C38: A Thousand Miles | D38: 237493 | E38: =D38/1000 -> 237.493 | F38: =FALSE() -> FALSE | G38: 5 | H38: =_xlfn.xlookup(G38, years!A$2:A$836, years!B$2:B$836) -> 2002 | I38: 75 | J38: 0.56 | K38: 0.825 | L38: =IF(K38>0.66,"High",IF(K38>0.33&K38<=0.66,"Medium","Low")) -> High | M38: -3.862 | N38: 0.0379 | O38: 0.323 | P38: 0 | Q38: 0.161 | R38: 0.268 | S38: =IF(R38 >= 0.5, "Positive", "Negative") -> Negative | T38: 94.931 | U38: Folk/Acoustic, pop
A39: 533 | B39: =_xlfn.xlookup(A39, artists!A$2:A$836, artists!B$2:B$836) -> Christina Perri | C39: A Thousand Years | D39: 285120 | E39: =D39/1000 -> 285.12 | F39: =FALSE() -> FALSE | G39: 14 | H39: =_xlfn.xlookup(G39, years!A$2:A$836, years!B$2:B$836) -> 2011 | I39: 70 | J39: 0.421 | K39: 0.407 | L39: =IF(K39>0.66,"High",IF(K39>0.33&K39<=0.66,"Medium","Low")) -> Low | M39: -7.445 | N39: 0.0267 | O39: 0.309 | P39: 0.000961 | Q39: 0.11 | R39: 0.161 | S39: =IF(R39 >= 0.5, "Positive", "Negative") -> Negative | T39: 139.028 | U39: pop
A40: 179 | B40: =_xlfn.xlookup(A40, artists!A$2:A$836, artists!B$2:B$836) -> Alicia Keys | C40: A Woman's Worth | D40: 303333 | E40: =D40/1000 -> 303.333 | F40: =FALSE() -> FALSE | G40: 4 | H40: =_xlfn.xlookup(G40, years!A$2:A$836, years!B$2:B$836) -> 2001 | I40: 52 | J40: 0.652 | K40: 0.41 | L40: =IF(K40>0.66,"High",IF(K40>0.33&K40<=0.66,"Medium","Low")) -> Low | M40: -8.323 | N40: 0.158 | O40: 0.333 | P40: 0 | Q40: 0.064 | R40: 0.495 | S40: =IF(R40 >= 0.5, "Positive", "Negative") -> Negative | T40: 75.09 | U40: pop, R&B
...

Sheet artists
A1: artist_id | B1: artist_name
A2: 1 | B2: Britney Spears
A3: 2 | B3: blink-182
A4: 3 | B4: Faith Hill
A5: 4 | B5: Bon Jovi
A6: 5 | B6: *NSYNC
A7: 6 | B7: Sisqo
A8: 7 | B8: Eminem
A9: 8 | B9: Robbie Williams
A10: 9 | B10: Destiny's Child
A11: 10 | B11: Modjo
A12: 11 | B12: Gigi D'Agostino
A13: 12 | B13: Eiffel 65
... A836: 835 | B836: Blanco Brown

Sheet years
A1: year_id | B1: year
A2: 1 | B2: 1998
A3: 2 | B3: 1999
A4: 3 | B4: 2000
A5: 4 | B5: 2001
A6: 5 | B6: 2002
A7: 6 | B7: 2003
A8: 7 | B8: 2004
A9: 8 | B9: 2005
A10: 9 | B10: 2006
A11: 10 | B11: 2007
A12: 11 | B12: 2008
A13: 12 | B13: 2009
... A24: 23 | B24: 2020

Sheet null_values
B1: artist_id | C1: song | D1: duration_ms | E1: explicit | F1: year_id | G1: popularity | H1: danceability | I1: energy | J1: loudness | K1: speechiness | L1: acousticness | M1: instrumentalness | N1: liveness | O1: valence | P1: tempo | Q1: genre
A2: Number of null values | B2: =COUNTBLANK(songs!A$2:A$2004) -> 61 | C2: =COUNTBLANK(songs!C$2:C$2004) -> 61 | D2: =COUNTBLANK(songs!D$2:D$2004) -> 61 | E2: =COUNTBLANK(songs!F$2:F$2004) -> 61 | F2: =COUNTBLANK(songs!G$2:G$2004) -> 61 | G2: =COUNTBLANK(songs!I$2:I$2004) -> 61 | H2: =COUNTBLANK(songs!J$2:J$2004) -> 61 | I2: =COUNTBLANK(songs!K$2:K$2004) -> 61 | J2: =COUNTBLANK(songs!M$2:M$2004) -> 61 | K2: =COUNTBLANK(songs!N$2:N$2004) -> 61 | L2: =COUNTBLANK(songs!O$2:O$2004) -> 61 | M2: =COUNTBLANK(songs!P$2:P$2004) -> 61 | N2: =COUNTBLANK(songs!Q$2:Q$2004) -> 61 | O2: =COUNTBLANK(songs!R$2:R$2004) -> 61 | P2: =COUNTBLANK(songs!T$2:T$2004) -> 61 | Q2: =COUNTBLANK(songs!U$2:U$2004) -> 61

Sheet EDA
B1: STATISTICS | M1: # OF UNIQUE VALUES
B2: duration_ms | C2: duration_seconds | D2: popularity | E2: danceability | F2: energy | G2: loudness | H2: speechiness | I2: acousticness | J2: instrumentalness | M2: artist_name | N2: song
A3: Count (number of records) | B3: =COUNT(songs!D$2:D$1943) -> 1942 | C3: =COUNT(songs!E$2:E$1943) -> 1942 | D3: =COUNT(songs!I$2:I$1943) -> 1942 | E3: =COUNT(songs!J$2:J$1943) -> 1942 | F3: =COUNT(songs!K$2:K$1943) -> 1942 | G3: =COUNT(songs!M$2:M$1943) -> 1942 | H3: =COUNT(songs!N$2:N$1943) -> 1942 | I3: =COUNT(songs!O$2:O$1943) -> 1942 | J3: =COUNT(songs!P$2:P$1943) -> 1942 | L3: Number of unique values | M3: =COUNTA(_xlfn.unique(songs!B$2:B$1943)) -> 835 | N3: =COUNTA(_xlfn.unique(songs!C$2:C$1943)) -> 1874
A4: Average | B4: =AVERAGE(songs!D$2:D$1943) -> 228644.26 | C4: =AVERAGE(songs!E$2:E$1943) -> 228.64426 | D4: =AVERAGE(songs!I$2:I$1943) -> 59.637487 | E4: =AVERAGE(songs!J$2:J$1943) -> 0.66780381 | F4: =AVERAGE(songs!K$2:K$1943) -> 0.72156797 | G4: =AVERAGE(songs!M$2:M$1943) -> -5.513465 | H4: =AVERAGE(songs!N$2:N$1943) -> 0.10388671 | I4: =AVERAGE(songs!O$2:O$1943) -> 0.12811396 | J4: =AVERAGE(songs!P$2:P$1943) -> 0.01536456
A5: Median | B5: =MEDIAN(songs!D$2:D$1943) -> 223219.5 | C5: =MEDIAN(songs!E$2:E$1943) -> 223.2195 | D5: =MEDIAN(songs!I$2:I$1943) -> 65 | E5: =MEDIAN(songs!J$2:J$1943) -> 0.676 | F5: =MEDIAN(songs!K$2:K$1943) -> 0.739 | G5: =MEDIAN(songs!M$2:M$1943) -> -5.2845 | H5: =MEDIAN(songs!N$2:N$1943) -> 0.061 | I5: =MEDIAN(songs!O$2:O$1943) -> 0.0557 | J5: =MEDIAN(songs!P$2:P$1943) -> 0
A6: First quartile | B6: =QUARTILE(songs!D$2:D$1943, 1) -> 203506 | C6: =QUARTILE(songs!E$2:E$1943, 1) -> 203.506 | D6: =QUARTILE(songs!I$2:I$1943, 1) -> 56 | E6: =QUARTILE(songs!J$2:J$1943, 1) -> 0.581 | F6: =QUARTILE(songs!K$2:K$1943, 1) -> 0.624 | G6: =QUARTILE(songs!M$2:M$1943, 1) -> -6.4895 | H6: =QUARTILE(songs!N$2:N$1943, 1) -> 0.0397 | I6: =QUARTILE(songs!O$2:O$1943, 1) -> 0.013525 | J6: =QUARTILE(songs!P$2:P$1943, 1) -> 0
A7: Minimum | B7: =MIN(songs!D$2:D$1943) -> 113000 | C7: =MIN(songs!E$2:E$1943) -> 113 | D7: =MIN(songs!I$2:I$1943) -> 0 | E7: =MIN(songs!J$2:J$1943) -> 0.129 | F7: =MIN(songs!K$2:K$1943) -> 0.0549 | G7: =MIN(songs!M$2:M$1943) -> -20.514 | H7: =MIN(songs!N$2:N$1943) -> 0.0232 | I7: =MIN(songs!O$2:O$1943) -> 1.92e-05 | J7: =MIN(songs!P$2:P$1943) -> 0

Sheet pivot_tables
H2: ARTIST WITH THE HIGHEST NUMBER OF SONGS | K2: Artist | L2: % of negative songs | M2: % of positive songs
A3: year | B3: Average of tempo | H3: Drake | I3: 23 | K3: Drake | L3: 0.60869565 | M3: 0.39130435
A4: 1998 | B4: 81.125 | H4: Rihanna | I4: 23 | K4: Rihanna | L4: 0.39130435 | M4: 0.60869565
A5: 1999 | B5: 122.705 | H5: Eminem | I5: 21 | K5: Eminem | L5: 0.33333333 | M5: 0.66666667
A6: 2000 | B6: 112.66087 | H6: Calvin Harris | I6: 20 | K6: Calvin Harris | L6: 0.25 | M6: 0.75
A7: 2001 | B7: 117.41488 | H7: Britney Spears | I7: 19 | K7: Britney Spears | L7: 0.26315789 | M7: 0.73684211
A8: 2002 | B8: 113.13156 | H8: David Guetta | I8: 18 | K8: David Guetta | L8: 0.55555556 | M8: 0.44444444
A9: 2003 | B9: 119.41037 | H9: Beyoncé | I9: 16 | K9: Beyoncé | L9: 0.5 | M9: 0.5
A10: 2004 | B10: 115.00748 | H10: Chris Brown | I10: 16 | K10: Chris Brown | L10: 0.375 | M10: 0.625
A11: 2005 | B11: 119.28991 | H11: Kanye West | I11: 16 | K11: Kanye West | L11: 0.625 | M11: 0.375
A12: 2006 | B12: 113.86545 | H12: Katy Perry | I12: 16 | K12: Katy Perry | L12: 0.3125 | M12: 0.6875
A13: 2007 | B13: 120.7118 | H13: Taylor Swift | I13: 16 | K13: Taylor Swift | L13: 0.5625 | M13: 0.4375
A14: 2008 | B14: 125.71456 | H14: Black Eyed Peas | I14: 14 | K14: Black Eyed Peas | L14: 0.35714286 | M14: 0.64285714
A15: 2009 | B15: 125.2184 | H15: P!nk | I15: 14 | K15: P!nk | L15: 0.28571429 | M15: 0.71428571
... A22: 2016 | B22: 120.88265 | H22: Jason Derulo | I22: 11 | K22: Jason Derulo | L22: 0.090909091 | M22: 0.90909091
A23: 2017 | B23: 120.04531 | K23: Usher | L23: 0.27272727 | M23: 0.72727273
A24: 2018 | B24: 118.66576 | K24: Nelly | L24: 0.18181818 | M24: 0.81818182
A25: 2019 | B25: 127.95299 | K25: Avril Lavigne | L25: 0.6 | M25: 0.4
A26: 2020 | B26: 128.143 | K26: Avicii | L26: 0.5 | M26: 0.5
A27: Total Result | B27: 120.14085 | K27: Flo Rida | L27: 0.3 | M27: 0.7
H28: AVERAGE TEMPO BY RELEASE YEAR OF SONG
H29: Year | I29: Average tempo (BPM)
H30: 1998 | I30: 81.125
H31: 1999 | I31: 122.705
H32: 2000 | I32: 112.66087
H33: 2001 | I33: 117.41488
H34: 2002 | I34: 113.13156
H35: 2003 | I35: 119.41037
H36: 2004 | I36: 115.00748
H37: 2005 | I37: 119.28991
H38: 2006 | I38: 113.86545
H39: 2007 | I39: 120.7118
H40: 2008 | I40: 125.71456
H41: 2009 | I41: 125.2184
... H52: 2020 | I52: 128.143
